ERROR 2022-12-02 07:32:59,873 log 241 Internal Server Error: /vnc
Traceback (most recent call last):
  File "C:\Users\Administrator\AppData\Local\Programs\Python\Python39\lib\site-packages\django\template\base.py", line 505, in parse
    compile_func = self.tags[command]
KeyError: 'static'

During handling of the above exception, another exception occurred:

Traceback (most recent call last):
  File "C:\Users\Administrator\AppData\Local\Programs\Python\Python39\lib\site-packages\asgiref\sync.py", line 472, in thread_handler
    raise exc_info[1]
  File "C:\Users\Administrator\AppData\Local\Programs\Python\Python39\lib\site-packages\django\core\handlers\exception.py", line 42, in inner
    response = await get_response(request)
  File "C:\Users\Administrator\AppData\Local\Programs\Python\Python39\lib\site-packages\django\core\handlers\base.py", line 253, in _get_response_async
    response = await wrapped_callback(
  File "C:\Users\Administrator\AppData\Local\Programs\Python\Python39\lib\site-packages\asgiref\sync.py", line 435, in __call__
    ret = await asyncio.wait_for(future, timeout=None)
  File "C:\Users\Administrator\AppData\Local\Programs\Python\Python39\lib\asyncio\tasks.py", line 442, in wait_for
    return await fut
  File "C:\Users\Administrator\AppData\Local\Programs\Python\Python39\lib\concurrent\futures\thread.py", line 58, in run
    result = self.fn(*self.args, **self.kwargs)
  File "C:\Users\Administrator\AppData\Local\Programs\Python\Python39\lib\site-packages\asgiref\sync.py", line 476, in thread_handler
    return func(*args, **kwargs)
  File "C:\Users\Administrator\Desktop\zm\MxPi\mx-raspberry-pi\mxpi\.\app\views.py", line 28, in vnc
    return render(request,'vnc.html')
  File "C:\Users\Administrator\AppData\Local\Programs\Python\Python39\lib\site-packages\django\shortcuts.py", line 24, in render
    content = loader.render_to_string(template_name, context, request, using=using)
  File "C:\Users\Administrator\AppData\Local\Programs\Python\Python39\lib\site-packages\django\template\loader.py", line 61, in render_to_string
    template = get_template(template_name, using=using)
  File "C:\Users\Administrator\AppData\Local\Programs\Python\Python39\lib\site-packages\django\template\loader.py", line 15, in get_template
    return engine.get_template(template_name)
  File "C:\Users\Administrator\AppData\Local\Programs\Python\Python39\lib\site-packages\django\template\backends\django.py", line 34, in get_template
    return Template(self.engine.get_template(template_name), self)
  File "C:\Users\Administrator\AppData\Local\Programs\Python\Python39\lib\site-packages\django\template\engine.py", line 176, in get_template
    template, origin = self.find_template(template_name)
  File "C:\Users\Administrator\AppData\Local\Programs\Python\Python39\lib\site-packages\django\template\engine.py", line 158, in find_template
    template = loader.get_template(name, skip=skip)
  File "C:\Users\Administrator\AppData\Local\Programs\Python\Python39\lib\site-packages\django\template\loaders\base.py", line 28, in get_template
    return Template(
  File "C:\Users\Administrator\AppData\Local\Programs\Python\Python39\lib\site-packages\django\template\base.py", line 154, in __init__
    self.nodelist = self.compile_nodelist()
  File "C:\Users\Administrator\AppData\Local\Programs\Python\Python39\lib\site-packages\django\template\base.py", line 200, in compile_nodelist
    return parser.parse()
  File "C:\Users\Administrator\AppData\Local\Programs\Python\Python39\lib\site-packages\django\template\base.py", line 507, in parse
    self.invalid_block_tag(token, command, parse_until)
  File "C:\Users\Administrator\AppData\Local\Programs\Python\Python39\lib\site-packages\django\template\base.py", line 568, in invalid_block_tag
    raise self.error(
django.template.exceptions.TemplateSyntaxError: Invalid block tag on line 21: 'static'. Did you forget to register or load this tag?
ERROR 2023-07-27 22:53:45,996 log 224 Internal Server Error: /files
Traceback (most recent call last):
  File "C:\Users\Administrator\AppData\Local\Programs\Python\Python310\lib\site-packages\asgiref\sync.py", line 472, in thread_handler
    raise exc_info[1]
  File "C:\Users\Administrator\AppData\Local\Programs\Python\Python310\lib\site-packages\django\core\handlers\exception.py", line 38, in inner
    response = await get_response(request)
  File "C:\Users\Administrator\AppData\Local\Programs\Python\Python310\lib\site-packages\django\core\handlers\base.py", line 233, in _get_response_async
    response = await wrapped_callback(request, *callback_args, **callback_kwargs)
  File "C:\Users\Administrator\AppData\Local\Programs\Python\Python310\lib\site-packages\asgiref\sync.py", line 435, in __call__
    ret = await asyncio.wait_for(future, timeout=None)
  File "C:\Users\Administrator\AppData\Local\Programs\Python\Python310\lib\asyncio\tasks.py", line 408, in wait_for
    return await fut
  File "C:\Users\Administrator\AppData\Local\Programs\Python\Python310\lib\concurrent\futures\thread.py", line 58, in run
    result = self.fn(*self.args, **self.kwargs)
  File "C:\Users\Administrator\AppData\Local\Programs\Python\Python310\lib\site-packages\asgiref\sync.py", line 476, in thread_handler
    return func(*args, **kwargs)
  File "C:\Users\Administrator\Desktop\MxPi\mx-raspberry-pi\mxpi\.\app\views.py", line 74, in files
    if file_obj.name=='blob':
AttributeError: 'NoneType' object has no attribute 'name'
